<?xml version="1.0"?>

<robot  xmlns:controller="http://playerstage.sourceforge.net/gazebo/xmlschema/#controller"
        xmlns:sensor="http://playerstage.sourceforge.net/gazebo/xmlschema/#sensor" 
        xmlns:xacro="http://www.ros.org/wiki/xacro" 
        name="HummingBird">

<!-- 
     At this time the robot name is used as prefix for the ros nodes.
     Common ROS msgs are used (or, to say better, abused...) in order
     to maintain the largest compatibility.
     
     This robot will subscribe the following nodes, according to the
     selected control input
        /${model_name}/input/position   (if <selectInput>position</selectInput>)
          this is a six value vector (geometry_msgs/Twist) containing current
          and desired position coordinates (x, y, z, x_des, y_des, z_des).
          You can test this type of input by executing rotopic on a terminal:
          rostopic pub /quad1/input/position geometry_msgs/Twist
          '{linear: {x: X_CUR, y: Y_CUR, z: Z_CUR}, angular: {x: X_DES, y: X_DES, z: Z_DES}}'
          
        /${model_name}/input/torques    (if <selectInput>torques</selectInput>)
          this is a four value vector (geometry_msgs/Quaternion) containing
          torques and thrust references (tx, ty, tz, T)
          
        /${model_name}/input/actual     (if <selectInput>actual</selectInput>)
          this is a four value vector (geometry_msgs/Quaternion) containing 
          angles and thrust references (roll, pitch, \dot{yaw}, T)
        
        /${model_name}/input/serial     (if <selectInput>serial</selectInput>)
          this is a std::string formatted according to AscTec HummingBird serial
          communication protocol modified by Sapienza DIAG LabRob
-->
<xacro:property name="id" value="0" />

<!-- GENERAL MACROS -->
<xacro:property name="PI"       value="3.141592653589793" />
<xacro:property name="HALF_PI"  value="1.570796326794897" />

<!-- MODEL (GEOMETRICAL) MACROS -->
<xacro:property name="body_size"  value="0.080" />

<xacro:property name="arm_length" value="0.160" />
<xacro:property name="arm_width"  value="0.005" />
<xacro:property name="arm_height" value="0.010" />
<xacro:property name="arm_ori_x"  value="-0.12" />

<xacro:property name="motor_radius" value="0.0127" />
<xacro:property name="motor_length" value="0.0100" />

<xacro:property name="prop_length" value="0.180" />
<xacro:property name="prop_width"  value="0.005" />
<xacro:property name="prop_height" value="0.001" />

<!-- MODEL (PHYSICAL) MACROS -->
<xacro:property name="body_mass"  value="0.300" />
<xacro:property name="arm_mass"   value="0.030" />
<xacro:property name="motor_mass" value="0.050" />
<xacro:property name="prop_mass"  value="0.002" />

<!-- MODEL (INERTIAL) MACROS -->
<xacro:macro name="body_inertia">
  <inertia ixx="1e-5"  ixy="1e-10"  ixz="1e-10" iyy="1e-5" iyz="1e-10" izz="1e-5" />  
</xacro:macro>

<xacro:macro name="arm_box_inertia">
  <inertia ixx="1e-5" ixy="0" ixz="0" iyy="1e-5" iyz="0" izz="1e-5" />
</xacro:macro>

<xacro:macro name="motor_box_inertia">
  <inertia ixx="1e-5" ixy="0" ixz="0" iyy="1e-5" iyz="0" izz="1e-5" />
</xacro:macro>

<!-- GAZEBO REFERENCES (FIX THESE) -->
  <material name="body_color">
    <color rgba=".1 .1 .1 1.0"/>
  </material>

  <gazebo reference="base_link">
    <material>Gazebo/Black</material>
  </gazebo>

  <gazebo reference="arm1">
    <material>Gazebo/Red</material>
  </gazebo>
  <gazebo reference="arm2">
    <material>Gazebo/Green</material>
  </gazebo>
  <gazebo reference="arm3">
    <material>Gazebo/Red</material>
  </gazebo>
  <gazebo reference="arm4">
    <material>Gazebo/Red</material>
  </gazebo>

  <gazebo reference="motor1">
    <material>Gazebo/Blue</material>
  </gazebo>
  <gazebo reference="motor2">
    <material>Gazebo/Blue</material>
  </gazebo>
  <gazebo reference="motor3">
    <material>Gazebo/Blue</material>
  </gazebo>
  <gazebo reference="motor4">
    <material>Gazebo/Blue</material>
  </gazebo>

  <gazebo reference="propeller1">
    <material>Gazebo/Red</material>
  </gazebo>
  <gazebo reference="propeller2">
    <material>Gazebo/Blue</material>
  </gazebo>
  <gazebo reference="propeller3">
    <material>Gazebo/Green</material>
  </gazebo>
  <gazebo reference="propeller4">
    <material>Gazebo/White</material>
  </gazebo>

<!-- CONTROLLER -->
<!-- BASE LINK -->
   <link name="base_link">
    <visual>
      <geometry>
        <box size="${body_size} ${body_size} ${body_size}"/>
      </geometry>
      <origin xyz="0 0 0" rpy="0 0 0"/>
      <material name="body_color" />
    </visual>

    <inertial>
      <origin xyz="0 0 0" rpy="0 0 0"/>
      <mass value="${body_mass}" />
      <inertia ixx="1e-5"  ixy="1e-10"  ixz="1e-10" iyy="1e-5" iyz="1e-10" izz="1e-5" />  
    </inertial>

    <collision>
      <geometry>
        <box size="${body_size} ${body_size} ${body_size}"/>
      </geometry>
    </collision>
  </link>

<!-- LINK 1 -->
  
<!-- Arm 1 -->
  <link name="arm1">
    <visual>
      <origin xyz="${-arm_ori_x} 0 0" rpy="0 0 0" />
      <geometry>
       <box size="${arm_length} ${arm_width} ${arm_height}"/>
      </geometry>
    </visual>

    <inertial>
      <mass value="${arm_mass}" />
      <inertia ixx="1e-5" ixy="0" ixz="0" iyy="1e-5" iyz="0" izz="1e-5" />
    </inertial>

    <collision>
      <geometry>
       <box size="${arm_length} ${arm_width} ${arm_height}"/>
      </geometry>
    </collision>
  </link>

<!-- Motor 1 -->
  <link name="motor1" >
    <inertial>
      <mass value="${motor_mass}" />
      <inertia ixx="1e-5" ixy="0" ixz="0" iyy="1e-5" iyz="0" izz="1e-5" />
    </inertial>

    <visual>
      <geometry>
        <cylinder radius="${motor_radius}" length="${motor_length}"/>
      </geometry>
      <material name="Cyan">
        <color rgba="0 0 1.0 1.0"/>
      </material>
    </visual>

    <collision>
      <geometry>
        <cylinder radius="${motor_radius}" length="${motor_length}"/>
      </geometry>
    </collision>
  </link>

<!-- Propeller 1 -->
 <link name="propeller1">
    <inertial>
      <mass value="${prop_mass}" />
      <inertia ixx="1e-5" ixy="0" ixz="0" iyy="1e-5" iyz="0" izz="1e-5" />
    </inertial>

    <visual>
      <geometry>
        <box size="${prop_length} ${prop_width} ${prop_height}"/>
      </geometry>
      <material name="Cyan" />
    </visual>

    <collision>
      <geometry>
        <box size="${prop_length} ${prop_width} ${prop_height}"/>
      </geometry>
    </collision>
  </link>

<!-- Joint 1 -->
  <joint name="body_arm1" type="fixed">
	<origin xyz="0 0 0" rpy="0 0 ${2 * HALF_PI}" />
	<parent link="base_link"/>
	<child link="arm1"/>
  </joint>

  <joint name="arm_motor1" type="continuous">
	<origin xyz="-0.20 0 0.01" rpy="0 0 0" />
	<axis xyz="0 0 1" />
	<parent link="arm1" />
	<child link="motor1" /> 
  </joint>

  <joint name="motor_prop1" type="fixed">
	<origin xyz="0 0 0.005" rpy="0 0 0" />
	<parent link="motor1" />
	<child  link="propeller1" />
  </joint>

<!-- LINK 2 -->
<!-- Arm 2 -->
  <link name="arm2">
    <visual>
      <origin xyz="0 ${-arm_ori_x} 0" rpy="0 0 0" />
      <geometry>
       <box size="${arm_length} ${arm_width} ${arm_height}"/>
      </geometry>
    </visual>

    <inertial>
      <mass value="${arm_mass}" />
      <inertia ixx="1e-5" ixy="0" ixz="0" iyy="1e-5" iyz="0" izz="1e-5" />
    </inertial>

    <collision>
      <geometry>
       <box size="${arm_length} ${arm_width} ${arm_height}"/>
      </geometry>
    </collision>
  </link>

<!-- Motor 2 -->
  <link name="motor2" >
    <inertial>
      <mass value="${motor_mass}" />
      <inertia ixx="1e-5" ixy="0" ixz="0" iyy="1e-5" iyz="0" izz="1e-5" />
    </inertial>

    <visual>
      <geometry>
        <cylinder radius="${motor_radius}" length="${motor_length}"/>
      </geometry>
      <material name="Cyan">
        <color rgba="0 0 1.0 1.0"/>
      </material>
    </visual>

    <collision>
      <geometry>
        <cylinder radius="${motor_radius}" length="${motor_length}"/>
      </geometry>
    </collision>
  </link>

<!-- Propeller 2 -->
 <link name="propeller2">
    <inertial>
      <mass value="${prop_mass}" />
      <inertia ixx="1e-5" ixy="0" ixz="0" iyy="1e-5" iyz="0" izz="1e-5" />
    </inertial>

    <visual>
      <geometry>
        <box size="${prop_length} ${prop_width} ${prop_height}"/>
      </geometry>
      <material name="Cyan" />
    </visual>

    <collision>
      <geometry>
        <box size="${prop_length} ${prop_width} ${prop_height}"/>
      </geometry>
    </collision>
  </link>

<!-- Joint 2 -->
  <joint name="body_arm2" type="fixed">
	<origin xyz="0 0 0" rpy="0 0 ${3 * HALF_PI}" />
	<parent link="base_link"/>
	<child link="arm2"/>
  </joint>

  <joint name="arm_motor2" type="continuous">
	<origin xyz="-0.20 0 0.01" rpy="0 0 0" />
	<axis xyz="0 0 1" />
	<parent link="arm2" />
	<child link="motor2" /> 
  </joint>

  <joint name="motor_prop2" type="fixed">
	<origin xyz="0 0 0.005" rpy="0 0 0" />
	<parent link="motor2" />
	<child  link="propeller2" />
  </joint>

<!-- LINK 3 -->
<!-- Arm 3 -->
  <link name="arm3">
    <visual>
      <origin xyz="${arm_ori_x} 0 0" rpy="0 0 0" />
      <geometry>
       <box size="${arm_length} ${arm_width} ${arm_height}"/>
      </geometry>
    </visual>

    <inertial>
      <mass value="${arm_mass}" />
      <inertia ixx="1e-5" ixy="0" ixz="0" iyy="1e-5" iyz="0" izz="1e-5" />
    </inertial>

    <collision>
      <geometry>
       <box size="${arm_length} ${arm_width} ${arm_height}"/>
      </geometry>
    </collision>
  </link>

<!-- Motor 3 -->
  <link name="motor3" >
    <inertial>
      <mass value="${motor_mass}" />
      <inertia ixx="1e-5" ixy="0" ixz="0" iyy="1e-5" iyz="0" izz="1e-5" />
    </inertial>

    <visual>
      <geometry>
        <cylinder radius="${motor_radius}" length="${motor_length}"/>
      </geometry>
      <material name="Cyan">
        <color rgba="0 0 1.0 1.0"/>
      </material>
    </visual>

    <collision>
      <geometry>
        <cylinder radius="${motor_radius}" length="${motor_length}"/>
      </geometry>
    </collision>
  </link>

<!-- Propeller 3 -->
 <link name="propeller3">
    <inertial>
      <mass value="${prop_mass}" />
      <inertia ixx="1e-5" ixy="0" ixz="0" iyy="1e-5" iyz="0" izz="1e-5" />
    </inertial>

    <visual>
      <geometry>
        <box size="${prop_length} ${prop_width} ${prop_height}"/>
      </geometry>
      <material name="Cyan" />
    </visual>

    <collision>
      <geometry>
        <box size="${prop_length} ${prop_width} ${prop_height}"/>
      </geometry>
    </collision>
  </link>

<!-- Joint 3 -->
  <joint name="body_arm3" type="fixed">
	<origin xyz="0 0 0" rpy="0 0 ${4 * HALF_PI}" />
	<parent link="base_link"/>
	<child link="arm3"/>
  </joint>

  <joint name="arm_motor3" type="continuous">
	<origin xyz="-0.20 0 0.01" rpy="0 0 0" />
	<axis xyz="0 0 1" />
	<parent link="arm3" />
	<child link="motor3" /> 
  </joint>

  <joint name="motor_prop3" type="fixed">
	<origin xyz="0 0 0.005" rpy="0 0 0" />
	<parent link="motor3" />
	<child  link="propeller3" />
  </joint>

<!-- LINK 4 -->
<!-- Arm 4 -->
  <link name="arm4">
    <visual>
      <origin xyz="0 ${arm_ori_x} 0" rpy="0 0 0" />
      <geometry>
       <box size="${arm_length} ${arm_width} ${arm_height}"/>
      </geometry>
    </visual>

    <inertial>
      <mass value="${arm_mass}" />
      <inertia ixx="1e-5" ixy="0" ixz="0" iyy="1e-5" iyz="0" izz="1e-5" />
    </inertial>

    <collision>
      <geometry>
       <box size="${arm_length} ${arm_width} ${arm_height}"/>
      </geometry>
    </collision>
  </link>

<!-- Motor 4 -->
  <link name="motor4" >
    <inertial>
      <mass value="${motor_mass}" />
      <inertia ixx="1e-5" ixy="0" ixz="0" iyy="1e-5" iyz="0" izz="1e-5" />
    </inertial>

    <visual>
      <geometry>
        <cylinder radius="${motor_radius}" length="${motor_length}"/>
      </geometry>
      <material name="Cyan">
        <color rgba="0 0 1.0 1.0"/>
      </material>
    </visual>

    <collision>
      <geometry>
        <cylinder radius="${motor_radius}" length="${motor_length}"/>
      </geometry>
    </collision>
  </link>

<!-- Propeller 4 -->
 <link name="propeller4">
    <inertial>
      <mass value="${prop_mass}" />
      <inertia ixx="1e-5" ixy="0" ixz="0" iyy="1e-5" iyz="0" izz="1e-5" />
    </inertial>

    <visual>
      <geometry>
        <box size="${prop_length} ${prop_width} ${prop_height}"/>
      </geometry>
      <material name="Cyan" />
    </visual>

    <collision>
      <geometry>
        <box size="${prop_length} ${prop_width} ${prop_height}"/>
      </geometry>
    </collision>
  </link>

<!-- Joint 4 -->
  <joint name="body_arm4" type="fixed">
	<origin xyz="0 0 0" rpy="0 0 ${5 * HALF_PI}" />
	<parent link="base_link"/>
	<child link="arm4"/>
  </joint>

  <joint name="arm_motor4" type="continuous">
	<origin xyz="-0.20 0 0.01" rpy="0 0 0" />
	<axis xyz="0 0 1" />
	<parent link="arm4" />
	<child link="motor4" /> 
  </joint>

  <joint name="motor_prop4" type="fixed">
	<origin xyz="0 0 0.005" rpy="0 0 0" />
	<parent link="motor4" />
	<child  link="propeller4" />
  </joint>

<gazebo>
  <controller:labrob_hubi_pluginss name="labrob_hubi_plugin" plugin="libhubi_controller.so">
    <alwaysOn>true</alwaysOn>
    <update>1000</update>
    <updateRate>1000.0</updateRate>
    <armLength>${arm_length}</armLength>
    <propellerThrust>3.5e-5</propellerThrust>
    <propellerDrag>7.5e-5</propellerDrag>
    <motorSpeed>1000.0</motorSpeed>
    <thrustScale>350.0</thrustScale>
    <enableAttitudeControl>true</enableAttitudeControl>
    <enablePositionControl>true</enablePositionControl>
    <enableAbsoluteError>true</enableAbsoluteError>
    <selectInput>position</selectInput>
    <enablePropellers>true</enablePropellers>
    <recordLog>true</recordLog>
  </controller:labrob_hubi_pluginss>
  <canonicalBody>base_link</canonicalBody>
</gazebo>
  
</robot>

